Workbook

Sheet Commandes_achat
A1: ID_Commande | B1: Date_Commande | C1: ID_Fournisseur | D1: ID_Article | E1: Usine | F1: Quantite | G1: Prix_Unitaire | H1: Date_Livraison_Prevue | I1: Date_Livraison_Reelle | J1: Statut_Commande | K1: Devise | L1: Acheteur | M1: Valeur_Commande | N1: Delai_Livraison_Jours | O1: Ecart_Prix | P1: Source_Systeme
A2: PO202600001 | B2: 45901 | C2: F014 | D2: A0003 | E2: MTL-01 | F2: 134 | G2: 352.87 | H2: 45957 | I2: 45957 | J2: Fermée | K2: CAD | L2: V. Lavoie | M2: =F2*G2 -> 47284.58 | N2: =IF(I2="","",I2-B2) -> 56 | O2: =IFERROR((G2-_xludf.XLOOKUP(D2,Articles!A:A,Articles!D:D))/_xludf.XLOOKUP(D2,Articles!A:A,Articles!D:D),"") | P2: Manuel
A3: PO202600002 | B3: 46085 | C3: F004 | D3: A0021 | E3: TRV-02 | F3: 231 | G3: 377.46 | H3: 46107 | I3: 46111 | J3: Fermée | K3: CAD | L3: M. Gagnon | M3: =F3*G3 -> 87193.26 | N3: =IF(I3="","",I3-B3) -> 26 | O3: =IFERROR((G3-_xludf.XLOOKUP(D3,Articles!A:A,Articles!D:D))/_xludf.XLOOKUP(D3,Articles!A:A,Articles!D:D),"") | P3: SAP
A4: PO202600003 | B4: 46074 | C4: F013 | D4: A0027 | E4: MTL-01 | F4: 192 | G4: 278.08 | H4: 46105 | I4: 46106 | J4: Fermée | K4: CAD | L4: S. Côté | M4: =F4*G4 -> 53391.36 | N4: =IF(I4="","",I4-B4) -> 32 | O4: =IFERROR((G4-_xludf.XLOOKUP(D4,Articles!A:A,Articles!D:D))/_xludf.XLOOKUP(D4,Articles!A:A,Articles!D:D),"") | P4: Excel
A5: PO202600004 | B5: 46102 | C5: F014 | D5: A0014 | E5: QC-01 | F5: 149 | G5: 389.6 | H5: 46115 | I5: 46122 | J5: Fermée | K5: CAD | L5: M. Gagnon | M5: =F5*G5 -> 58050.4 | N5: =IF(I5="","",I5-B5) -> 20 | O5: =IFERROR((G5-_xludf.XLOOKUP(D5,Articles!A:A,Articles!D:D))/_xludf.XLOOKUP(D5,Articles!A:A,Articles!D:D),"") | P5: SAP
A6: PO202600005 | B6: 45973 | C6: F003 | D6: A0043 | E6: TRV-02 | F6: 132 | G6: 129.53 | H6: 46022 | I6: 46032 | J6: Ouverte | K6: CAD | L6: S. Côté | M6: =F6*G6 -> 17097.96 | N6: =IF(I6="","",I6-B6) -> 59 | O6: =IFERROR((G6-_xludf.XLOOKUP(D6,Articles!A:A,Articles!D:D))/_xludf.XLOOKUP(D6,Articles!A:A,Articles!D:D),"") | P6: Manuel
A7: PO202600006 | B7: 45938 | C7: F007 | D7: A0015 | E7: TRV-02 | F7: 7 | G7: 88.53 | H7: 45973 | J7: Fermée | K7: CAD | L7: J. Bouchard | M7: =F7*G7 -> 619.71 | N7: =IF(I7="","",I7-B7) | O7: =IFERROR((G7-_xludf.XLOOKUP(D7,Articles!A:A,Articles!D:D))/_xludf.XLOOKUP(D7,Articles!A:A,Articles!D:D),"") | P7: Excel
A8: PO202600007 | B8: 45963 | C8: F013 | D8: A0032 | E8: QC-01 | F8: 38 | G8: 68.9 | H8: 45982 | I8: 45981 | J8: Fermée | K8: CAD | L8: A. Tremblay | M8: =F8*G8 -> 2618.2 | N8: =IF(I8="","",I8-B8) -> 18 | O8: =IFERROR((G8-_xludf.XLOOKUP(D8,Articles!A:A,Articles!D:D))/_xludf.XLOOKUP(D8,Articles!A:A,Articles!D:D),"") | P8: SAP
A9: PO202600008 | B9: 46118 | C9: F008 | D9: A0036 | E9: QC-01 | F9: 32 | G9: 298.83 | H9: 46150 | I9: 46162 | J9: Annulée | K9: CAD | L9: V. Lavoie | M9: =F9*G9 -> 9562.56 | N9: =IF(I9="","",I9-B9) -> 44 | O9: =IFERROR((G9-_xludf.XLOOKUP(D9,Articles!A:A,Articles!D:D))/_xludf.XLOOKUP(D9,Articles!A:A,Articles!D:D),"") | P9: SAP
A10: PO202600009 | B10: 46113 | C10: F014 | D10: A0033 | E10: MTL-01 | F10: 233 | G10: 259.6 | H10: 46125 | I10: 46141 | J10: Fermée | K10: CAD | L10: V. Lavoie | M10: =F10*G10 -> 60486.8 | N10: =IF(I10="","",I10-B10) -> 28 | O10: =IFERROR((G10-_xludf.XLOOKUP(D10,Articles!A:A,Articles!D:D))/_xludf.XLOOKUP(D10,Articles!A:A,Articles!D:D),"") | P10: Excel
A11: PO202600010 | B11: 45971 | C11: F004 | D11: A0032 | E11: TRV-01 | F11: 113 | G11: 57.48 | H11: 45994 | I11: 45994 | J11: Fermée | K11: CAD | L11: M. Gagnon | M11: =F11*G11 -> 6495.24 | N11: =IF(I11="","",I11-B11) -> 23 | O11: =IFERROR((G11-_xludf.XLOOKUP(D11,Articles!A:A,Articles!D:D))/_xludf.XLOOKUP(D11,Articles!A:A,Articles!D:D),"") | P11: SAP
A12: PO202600011 | B12: 45999 | C12: F914 | D12: A0010 | E12: QC-01 | F12: 178 | G12: 192.09 | H12: 46051 | I12: 46050 | J12: Fermée | K12: CAD | L12: J. Bouchard | M12: =F12*G12 -> 34192.02 | N12: =IF(I12="","",I12-B12) -> 51 | O12: =IFERROR((G12-_xludf.XLOOKUP(D12,Articles!A:A,Articles!D:D))/_xludf.XLOOKUP(D12,Articles!A:A,Articles!D:D),"") | P12: SAP
A13: PO202600012 | B13: 46114 | C13: F007 | D13: A0004 | E13: QC-01 | F13: 108 | G13: 194.95 | H13: 46159 | I13: 46156 | J13: Partiellement reçue | K13: CAD | L13: J. Bouchard | M13: =F13*G13 -> 21054.6 | N13: =IF(I13="","",I13-B13) -> 42 | O13: =IFERROR((G13-_xludf.XLOOKUP(D13,Articles!A:A,Articles!D:D))/_xludf.XLOOKUP(D13,Articles!A:A,Articles!D:D),"") | P13: Manuel
A14: PO202600013 | B14: 45977 | C14: F012 | D14: A0001 | E14: TRV-02 | F14: 193 | G14: 215.46 | H14: 45990 | I14: 46002 | J14: Fermée | K14: CAD | L14: J. Bouchard | M14: =F14*G14 -> 41583.78 | N14: =IF(I14="","",I14-B14) -> 25 | O14: =IFERROR((G14-_xludf.XLOOKUP(D14,Articles!A:A,Articles!D:D))/_xludf.XLOOKUP(D14,Articles!A:A,Articles!D:D),"") | P14: SAP
A15: PO202600014 | B15: 46012 | C15: F009 | D15: A0015 | E15: TRV-02 | F15: 125 | G15: 158.03 | H15: 46045 | I15: 46049 | J15: Fermée | K15: CAD | L15: V. Lavoie | M15: =F15*G15 -> 19753.75 | N15: =IF(I15="","",I15-B15) -> 37 | O15: =IFERROR((G15-_xludf.XLOOKUP(D15,Articles!A:A,Articles!D:D))/_xludf.XLOOKUP(D15,Articles!A:A,Articles!D:D),"") | P15: Excel
A16: PO202600015 | B16: 46001 | C16: F004 | D16: A0035 | E16: QC-01 | F16: 152 | G16: 172.45 | H16: 46054 | I16: 46053 | J16: Fermée | K16: CAD | L16: M. Gagnon | M16: =F16*G16 -> 26212.4 | N16: =IF(I16="","",I16-B16) -> 52 | O16: =IFERROR((G16-_xludf.XLOOKUP(D16,Articles!A:A,Articles!D:D))/_xludf.XLOOKUP(D16,Articles!A:A,Articles!D:D),"") | P16: SAP
A17: PO202600016 | B17: 45998 | C17: F009 | D17: A0004 | E17: QC-01 | F17: 84 | G17: 285.7 | H17: 46039 | I17: 46041 | J17: Fermée | K17: CAD | L17: S. Côté | M17: =F17*G17 -> 23998.8 | N17: =IF(I17="","",I17-B17) -> 43 | O17: =IFERROR((G17-_xludf.XLOOKUP(D17,Articles!A:A,Articles!D:D))/_xludf.XLOOKUP(D17,Articles!A:A,Articles!D:D),"") | P17: SAP
A18: PO202600017 | B18: 45905 | C18: F016 | D18: A0006 | E18: TRV-01 | F18: 192 | G18: 290.34 | H18: 45927 | I18: 45927 | J18: Fermée | K18: CAD | L18: A. Tremblay | M18: =F18*G18 -> 55745.28 | N18: =IF(I18="","",I18-B18) -> 22 | O18: =IFERROR((G18-_xludf.XLOOKUP(D18,Articles!A:A,Articles!D:D))/_xludf.XLOOKUP(D18,Articles!A:A,Articles!D:D),"") | P18: Excel
A19: PO202600018 | B19: 46115 | C19: F019 | D19: A0016 | E19: TRV-02 | F19: 6 | G19: 187.14 | H19: 46171 | I19: 46171 | J19: Fermée | K19: CAD | L19: J. Bouchard | M19: =F19*G19 -> 1122.84 | N19: =IF(I19="","",I19-B19) -> 56 | O19: =IFERROR((G19-_xludf.XLOOKUP(D19,Articles!A:A,Articles!D:D))/_xludf.XLOOKUP(D19,Articles!A:A,Articles!D:D),"") | P19: SAP
... A37: PO202600036 | B37: 45974 | C37: F008 | D37: A0003 | E37: TRV-02 | F37: 181 | G37: 473.5 | H37: 46029 | I37: 46028 | J37: Fermée | K37: CAD | L37: J. Bouchard | M37: =F37*G37 -> 85703.5 | N37: =IF(I37="","",I37-B37) -> 54 | O37: =IFERROR((G37-_xludf.XLOOKUP(D37,Articles!A:A,Articles!D:D))/_xludf.XLOOKUP(D37,Articles!A:A,Articles!D:D),"") | P37: Manuel
A38: PO202600037 | B38: 45958 | C38: F018 | D38: A0008 | E38: MTL-01 | F38: 166 | G38: 377.11 | H38: 46001 | J38: Ouverte | K38: CAD | L38: V. Lavoie | M38: =F38*G38 -> 62600.26 | N38: =IF(I38="","",I38-B38) | O38: =IFERROR((G38-_xludf.XLOOKUP(D38,Articles!A:A,Articles!D:D))/_xludf.XLOOKUP(D38,Articles!A:A,Articles!D:D),"") | P38: SAP
A39: PO202600038 | B39: 46013 | C39: F010 | D39: A0037 | E39: QC-01 | F39: 0 | G39: 435.35 | H39: 46071 | I39: 46075 | J39: Partiellement reçue | K39: CAD | L39: J. Bouchard | M39: =F39*G39 -> 0 | N39: =IF(I39="","",I39-B39) -> 62 | O39: =IFERROR((G39-_xludf.XLOOKUP(D39,Articles!A:A,Articles!D:D))/_xludf.XLOOKUP(D39,Articles!A:A,Articles!D:D),"") | P39: SAP
A40: PO202600039 | B40: 45911 | C40: F020 | D40: A0006 | E40: TRV-01 | F40: 228 | G40: 281.1 | H40: 45933 | I40: 45940 | J40: Ouverte | K40: CAD | L40: S. Côté | M40: =F40*G40 -> 64090.8 | N40: =IF(I40="","",I40-B40) -> 29 | O40: =IFERROR((G40-_xludf.XLOOKUP(D40,Articles!A:A,Articles!D:D))/_xludf.XLOOKUP(D40,Articles!A:A,Articles!D:D),"") | P40: SAP
A41: PO202600040 | B41: 46096 | C41: F015 | D41: A0037 | E41: QC-01 | F41: 194 | G41: 396.66 | H41: 46158 | I41: 46165 | J41: Partiellement reçue | K41: CAD | L41: J. Bouchard | M41: =F41*G41 -> 76952.04 | N41: =IF(I41="","",I41-B41) -> 69 | O41: =IFERROR((G41-_xludf.XLOOKUP(D41,Articles!A:A,Articles!D:D))/_xludf.XLOOKUP(D41,Articles!A:A,Articles!D:D),"") | P41: SAP
A42: PO202600041 | B42: 45990 | C42: F016 | D42: A0006 | E42: QC-01 | F42: 105 | G42: 272.6 | H42: 46017 | I42: 46016 | J42: Partiellement reçue | K42: CAD | L42: S. Côté | M42: =F42*G42 -> 28623 | N42: =IF(I42="","",I42-B42) -> 26 | O42: =IFERROR((G42-_xludf.XLOOKUP(D42,Articles!A:A,Articles!D:D))/_xludf.XLOOKUP(D42,Articles!A:A,Articles!D:D),"") | P42: SAP
A43: PO202600042 | B43: 46109 | C43: F013 | D43: A0043 | E43: QC-01 | F43: 195 | G43: 200.27 | H43: 46156 | I43: 46155 | J43: Fermée | K43: CAD | L43: V. Lavoie | M43: =F43*G43 -> 39052.65 | N43: =IF(I43="","",I43-B43) -> 46 | O43: =IFERROR((G43-_xludf.XLOOKUP(D43,Articles!A:A,Articles!D:D))/_xludf.XLOOKUP(D43,Articles!A:A,Articles!D:D),"") | P43: SAP
A44: PO202600043 | B44: 46019 | C44: F018 | D44: A0001 | E44: QC-01 | F44: 106 | G44: 193.01 | H44: 46034 | I44: 46058 | J44: Fermée | K44: CAD | L44: A. Tremblay | M44: =F44*G44 -> 20459.06 | N44: =IF(I44="","",I44-B44) -> 39 | O44: =IFERROR((G44-_xludf.XLOOKUP(D44,Articles!A:A,Articles!D:D))/_xludf.XLOOKUP(D44,Articles!A:A,Articles!D:D),"") | P44: SAP
A45: PO202600044 | B45: 46041 | C45: F009 | D45: A0014 | E45: TRV-02 | F45: 34 | G45: 425.96 | H45: 46056 | I45: 46063 | J45: Ouverte | K45: CAD | L45: M. Gagnon | M45: =F45*G45 -> 14482.64 | N45: =IF(I45="","",I45-B45) -> 22 | O45: =IFERROR((G45-_xludf.XLOOKUP(D45,Articles!A:A,Articles!D:D))/_xludf.XLOOKUP(D45,Articles!A:A,Articles!D:D),"") | P45: Manuel
A46: PO202600045 | B46: 45904 | C46: F018 | D46: A0020 | E46: TRV-02 | F46: 142 | G46: 87.64 | H46: 45948 | I46: 45947 | J46: Fermée | K46: CAD | L46: J. Bouchard | M46: =F46*G46 -> 12444.88 | N46: =IF(I46="","",I46-B46) -> 43 | O46: =IFERROR((G46-_xludf.XLOOKUP(D46,Articles!A:A,Articles!D:D))/_xludf.XLOOKUP(D46,Articles!A:A,Articles!D:D),"") | P46: SAP
A47: PO202600046 | B47: 46081 | C47: F017 | D47: A9562 | E47: QC-01 | F47: 70 | G47: 213.19 | H47: 46145 | I47: 46152 | J47: Ouverte | K47: CAD | L47: M. Gagnon | M47: =F47*G47 -> 14923.3 | N47: =IF(I47="","",I47-B47) -> 71 | O47: =IFERROR((G47-_xludf.XLOOKUP(D47,Articles!A:A,Articles!D:D))/_xludf.XLOOKUP(D47,Articles!A:A,Articles!D:D),"") | P47: SAP
A48: PO202600047 | B48: 46092 | C48: F017 | D48: A0039 | E48: MTL-01 | F48: 226 | G48: 283.29 | H48: 46120 | I48: 46121 | J48: Fermée | K48: CAD | L48: V. Lavoie | M48: =F48*G48 -> 64023.54 | N48: =IF(I48="","",I48-B48) -> 29 | O48: =IFERROR((G48-_xludf.XLOOKUP(D48,Articles!A:A,Articles!D:D))/_xludf.XLOOKUP(D48,Articles!A:A,Articles!D:D),"") | P48: Excel
A49: PO202600048 | B49: 45973 | C49: F001 | D49: A0018 | E49: QC-01 | F49: 186 | G49: 409.81 | H49: 46022 | I49: 46029 | J49: Partiellement reçue | K49: CAD | L49: S. Côté | M49: =F49*G49 -> 76224.66 | N49: =IF(I49="","",I49-B49) -> 56 | O49: =IFERROR((G49-_xludf.XLOOKUP(D49,Articles!A:A,Articles!D:D))/_xludf.XLOOKUP(D49,Articles!A:A,Articles!D:D),"") | P49: SAP
A50: PO202600049 | B50: 46096 | C50: F018 | D50: A0022 | E50: QC-01 | F50: 140 | G50: 248.33 | H50: 46124 | I50: 46146 | J50: Annulée | K50: CAD | L50: M. Gagnon | M50: =F50*G50 -> 34766.2 | N50: =IF(I50="","",I50-B50) -> 50 | O50: =IFERROR((G50-_xludf.XLOOKUP(D50,Articles!A:A,Articles!D:D))/_xludf.XLOOKUP(D50,Articles!A:A,Articles!D:D),"") | P50: SAP
... A60: PO202600059 | B60: 45998 | C60: F008 | D60: A0007 | E60: QC-01 | F60: 147 | G60: 225.31 | H60: 46022 | I60: 46023 | J60: Ouverte | K60: CAD | L60: S. Côté | M60: =F60*G60 -> 33120.57 | N60: =IF(I60="","",I60-B60) -> 25 | O60: =IFERROR((G60-_xludf.XLOOKUP(D60,Articles!A:A,Articles!D:D))/_xludf.XLOOKUP(D60,Articles!A:A,Articles!D:D),"") | P60: Excel
A61: PO202600060 | B61: 46076 | C61: F019 | D61: A0001 | E61: TRV-02 | F61: 200 | G61: 239.16 | H61: 46083 | J61: Partiellement reçue | K61: CAD | L61: V. Lavoie | M61: =F61*G61 -> 47832 | N61: =IF(I61="","",I61-B61) | O61: =IFERROR((G61-_xludf.XLOOKUP(D61,Articles!A:A,Articles!D:D))/_xludf.XLOOKUP(D61,Articles!A:A,Articles!D:D),"") | P61: Manuel
A62: PO202600061 | B62: 46063 | C62: F008 | D62: A0023 | E62: TRV-01 | F62: 49 | G62: 117.62 | H62: 46101 | I62: 46101 | J62: Fermée | K62: CAD | L62: S. Côté | M62: =F62*G62 -> 5763.38 | N62: =IF(I62="","",I62-B62) -> 38 | O62: =IFERROR((G62-_xludf.XLOOKUP(D62,Articles!A:A,Articles!D:D))/_xludf.XLOOKUP(D62,Articles!A:A,Articles!D:D),"") | P62: Manuel
A63: PO202600062 | B63: 46049 | C63: F002 | D63: A0029 | E63: TRV-02 | F63: -5 | G63: 137.33 | H63: 46091 | I63: 46092 | J63: Fermée | K63: CAD | L63: M. Gagnon | M63: =F63*G63 -> -686.65 | N63: =IF(I63="","",I63-B63) -> 43 | O63: =IFERROR((G63-_xludf.XLOOKUP(D63,Articles!A:A,Articles!D:D))/_xludf.XLOOKUP(D63,Articles!A:A,Articles!D:D),"") | P63: SAP
A64: PO202600063 | B64: 46036 | C64: F012 | D64: A0035 | E64: MTL-01 | F64: 129 | G64: 190.17 | H64: 46091 | I64: 46092 | J64: Partiellement reçue | K64: CAD | L64: S. Côté | M64: =F64*G64 -> 24531.93 | N64: =IF(I64="","",I64-B64) -> 56 | O64: =IFERROR((G64-_xludf.XLOOKUP(D64,Articles!A:A,Articles!D:D))/_xludf.XLOOKUP(D64,Articles!A:A,Articles!D:D),"") | P64: Manuel
A65: PO202600064 | B65: 45920 | C65: F015 | D65: A0008 | E65: MTL-01 | F65: 37 | G65: 453.64 | H65: 45962 | I65: 45966 | J65: Annulée | K65: CAD | L65: A. Tremblay | M65: =F65*G65 -> 16784.68 | N65: =IF(I65="","",I65-B65) -> 46 | O65: =IFERROR((G65-_xludf.XLOOKUP(D65,Articles!A:A,Articles!D:D))/_xludf.XLOOKUP(D65,Articles!A:A,Articles!D:D),"") | P65: Excel
A66: PO202600065 | B66: 45968 | C66: F001 | D66: A0026 | E66: MTL-01 | F66: 138 | G66: 506.45 | H66: 45991 | I66: 45992 | J66: Fermée | K66: CAD | L66: A. Tremblay | M66: =F66*G66 -> 69890.1 | N66: =IF(I66="","",I66-B66) -> 24 | O66: =IFERROR((G66-_xludf.XLOOKUP(D66,Articles!A:A,Articles!D:D))/_xludf.XLOOKUP(D66,Articles!A:A,Articles!D:D),"") | P66: Excel
...

Sheet Fournisseurs
A1: ID_Fournisseur | B1: Nom_Fournisseur | C1: Pays | D1: Categorie_Fournisseur | E1: Statut_Approvisionnement | F1: Conditions_Paiement | G1: Niveau_Risque | H1: Score_Risque | I1: Date_Evaluation_Risque
A2: F001 | B2: Ferantis | C2: États-Unis | D2: Composants | E2: Approuvé | F2: Net 45 | G2: Moyen | H2: 59 | I2: 46044
A3: F002 | B3: Nordex | C3: France | D3: Matières premières | E3: Approuvé | F3: Net 30 | G3: Moyen | H3: 38 | I3: 46029
A4: F003 | B4: Gagnon Inc | C4: États-Unis | D4: Emballage | E4: Approuvé | F4: 2% 10 Net 30 | G4: Faible | H4: 29 | I4: 46068
A5: F004 | B5: Nordex | C5: États-Unis | D5: Maintenance | E5: Non approuvé | F5: Net 60 | G5: Moyen | H5: 63 | I5: 46086
A6: F005 | B6: Omnitek | C6: Canada | D6: Maintenance | E6: Approuvé | F6: Net 30 | G6: Faible | H6: 34 | I6: 46093
A7: F006 | B7: Solvex | C7: France | D7: Emballage | E7: Approuvé | F7: Net 30 | G7: Moyen | H7: 37 | I7: 46115
A8: F007 | B8: Valtrix | C8: Mexique | D8: Emballage | E8: Approuvé | F8: Net 45 | G8: Moyen | H8: 55 | I8: 46024
A9: F008 | B9: Ferantis | C9: États-Unis | D9: Matières premières | E9: Approuvé | F9: 2% 10 Net 30 | G9: Moyen | H9: 45 | I9: 46096
A10: F009 | B10: Nordex | C10: Mexique | D10: Composants | E10: Non approuvé | F10: Net 60 | G10: Moyen | H10: 41 | I10: 46042
A11: F010 | B11: Solvex | C11: États-Unis | D11: Maintenance | E11: Approuvé | F11: 2% 10 Net 30 | G11: Moyen | H11: 59 | I11: 46102
A12: F011 | B12: Valtrix | C12: Canada | D12: Composants | E12: Approuvé | F12: Net 30 | G12: Moyen | H12: 57 | I12: 46094
A13: F012 | B13: Nordex | C13: Allemagne | D13: Transport | E13: Approuvé | F13: Net 45 | G13: Faible | H13: 16 | I13: 46125
... A21: F020 | B21: Solvex | C21: Mexique | D21: Composants | E21: Approuvé | F21: Net 30 | G21: Faible | H21: 21 | I21: 46072

Sheet Articles
A1: ID_Article | B1: Description_Article | C1: Groupe_Article | D1: Prix_Standard | E1: Criticite | F1: Delai_Approvisionnement_Jours | G1: Type_Article | H1: Unite_Mesure
A2: A0001 | B2: Article 001 - Acier | C2: Acier | D2: 222.81 | E2: Faible | F2: 9 | G2: Composant | H2: KG
A3: A0002 | B3: Article 002 - Emballage | C3: Emballage | D3: 251.01 | E3: Moyenne | F3: 21 | G3: Pièce de rechange | H3: KG
A4: A0003 | B4: Article 003 - Filtres | C4: Filtres | D4: 312.92 | E4: Moyenne | F4: 50 | G4: Produit fini | H4: M
A5: A0004 | B5: Article 004 - Emballage | C5: Emballage | D5: 201.64 | E5: Moyenne | F5: 38 | G5: Pièce de rechange | H5: EA
A6: A0005 | B6: Article 005 - Électronique | C6: Électronique | D6: 157.43 | E6: Faible | F6: 42 | G6: Composant | H6: KG
A7: A0006 | B7: Article 006 - Acier | C7: Acier | D7: 286.95 | E7: Faible | F7: 19 | G7: Matière première | H7: EA
A8: A0007 | B8: Article 007 - Quincaillerie | C8: Quincaillerie | D8: 235.26 | E8: Faible | F8: 22 | G8: Pièce de rechange | H8: KG
A9: A0008 | B9: Article 008 - Filtres | C9: Filtres | D9: 421.5 | E9: Faible | F9: 41 | G9: Pièce de rechange | H9: KG
A10: A0009 | B10: Article 009 - Quincaillerie | C10: Quincaillerie | D10: 187.92 | E10: Moyenne | F10: 11 | G10: Matière première | H10: M
A11: A0010 | B11: Article 010 - Hydraulique | C11: Hydraulique | D11: 214.42 | E11: Moyenne | F11: 51 | G11: Matière première | H11: EA
A12: A0011 | B12: Article 011 - Acier | C12: Acier | D12: 157.97 | E12: Moyenne | F12: 60 | G12: Matière première | H12: KG
A13: A0012 | B13: Article 012 - Électronique | C13: Électronique | D13: 206.29 | E13: Faible | F13: 32 | G13: Composant | H13: L
... A46: A0045 | B46: Article 045 - Filtres | C46: Filtres | D46: 59.12 | E46: Critique | F46: 41 | G46: Composant | H46: L

Sheet Inventaire
A1: ID_Article | B1: Usine | C1: Stock_Actuel | D1: Point_Commande | E1: Stock_Securite | F1: Date_Derniere_MAJ | G1: Valeur_Stock | H1: Statut_Stock
A2: A0001 | B2: QC-01 | C2: 174 | D2: 105 | E2: 43 | F2: 45996 | G2: 38768.94 | H2: OK
A3: A0001 | B3: MTL-01 | C3: 156 | D3: 115 | E3: 37 | F3: 46047 | G3: 34758.36 | H3: OK
A4: A0002 | B4: MTL-01 | C4: 167 | D4: 50 | E4: 26 | F4: 46071 | G4: 41918.67 | H4: OK
A5: A0002 | B5: TRV-02 | C5: 86 | D5: 74 | E5: 43 | F5: 46052 | G5: 21586.86 | H5: OK
A6: A0003 | B6: TRV-01 | C6: 3 | D6: 27 | E6: 14 | F6: 46018 | G6: 938.76 | H6: Sous seuil
A7: A0003 | B7: MTL-01 | C7: 185 | D7: 114 | E7: 24 | F7: 46126 | G7: 57890.2 | H7: OK
A8: A0004 | B8: TRV-01 | C8: 15 | D8: 80 | E8: 48 | F8: 45978 | G8: 3024.6 | H8: Sous seuil
A9: A0004 | B9: QC-01 | C9: 168 | D9: 58 | E9: 34 | F9: 46085 | G9: 33875.52 | H9: OK
A10: A0005 | B10: TRV-01 | C10: 75 | D10: 72 | E10: 26 | F10: 46016 | G10: 11807.25 | H10: OK
A11: A0005 | B11: MTL-01 | C11: 109 | D11: 95 | E11: 59 | F11: 46050 | G11: 17159.87 | H11: OK
A12: A0006 | B12: MTL-01 | C12: 24 | D12: 43 | E12: 27 | F12: 46117 | G12: 6886.8 | H12: Sous seuil
A13: A0006 | B13: TRV-01 | C13: 45 | D13: 91 | E13: 26 | F13: 46081 | G13: 12912.75 | H13: Sous seuil
... A91: A0045 | B91: MTL-01 | C91: 200 | D91: 159 | E91: 24 | F91: 46127 | G91: 11824 | H91: OK

Sheet Dictionnaire
A1: Champ | B1: Description
A2: Projet | B2: Tableau de bord Power BI pour le contrôle qualité des données ERP
A3: Objectif | B3: Simuler des extractions ERP/SAP afin de détecter automatiquement des anomalies opérationnelles.
A4: Langue | B4: Français - Québec
A5: Période simulée | B5: 2025-09 à 2026-04
A6: Anomalies intégrées | B6: Fournisseur inexistant, article inexistant, fournisseur non approuvé, quantité négative ou nulle, écart de prix > 20 %, livraison en retard, date de livraison manquante, stock sous seuil, stock critique.
A7: Utilisation | B7: Charger les quatre tables dans Power BI, créer les relations par ID_Fournisseur et ID_Article, puis construire les contrôles en Power Query/DAX.
